Workbook

Sheet data_survey
A1: Timestamp | B1: Quê quán (tỉnh thành trước khi sáp nhập) | C1: Giới tính sinh học | D1: GTSH_norm | E1: Xu hướng tính dục | F1: XHTD_norm | G1: Tôn giáo | H1: tongiao_norm | I1: Tình trạng sinh sống | J1: live_norm | K1: Tình trạng học lực của học kỳ trước | L1: hocluc_norm | M1: Bạn có cảm thấy ngành học không phù hợp với bản thân không? | N1: nganhphuhop_norm | O1: Bạn có đang đi làm thêm không | P1: lamthem_norm | Q1: Bao nhiêu công việc bạn đang làm? | R1: norm | S1: Công việc làm thêm | U1: Tần suất làm thêm | W1: norm | X1: Bao nhiêu phần trăm thu nhập của bạn cho chương trình học hiện tại? Điền giá trị 0-100 | Y1: Mỗi tháng bạn tiết kiệm được bao nhiêu phần trăm so với thu thập? Điền giá trị 0-100 | Z1: Việc sống xa gia đình có khiến bạn căng thẳng? | AA1: cangthangxagd_norm | AB1: Bạn có bị khuyết tật/ bỏng mặt hoặc vùng khác khiến mất thẩm mỹ không? | AC1: Bạn có bị đối xử bất công vì bất kỳ lý do nào sau đây không? | AD1: Bạn có lo lắng về việc làm sau khi tốt nghiệp đại học? | AE1: Gia đình có gây áp lực về điểm số, ngành học, sự nghiệp? | AF1: Bạn có cảm thấy áp lực phải đạt điểm cao / bằng cấp tốt? | AG1: Áp lực học tập khiến bạn cảm thấy căng thẳng / tinh thần giảm sút mức nào? | AH1: Mâu thuẫn với gia đình ảnh hưởng đến cảm xúc của bạn không? | AI1: Bạn có từng gặp xung đột trong tình yêu gây stress? | AK1: Việc chia tay/đổ vỡ có ảnh hưởng đến tâm lý của bạn mức nào? | AM1: Tình trạng mối quan hệ của bạn | AO1: Bạn đã có em bé chưa | AP1: Trong 2 tuần qua, bạn có dấu hiệu nào sau đây: 9 câu hỏi sau đây, lựa chọn theo mức độ mỗi câu: Không có - Vài ngày - Hơn một nửa số ngày - Gần như mỗi ngày 1. Ít quan tâm hoặc không còn thích thú làm mọi việc? (Little interest or pleasure in doing things?) | AQ1: 2. Cảm thấy chán nản, buồn bã hoặc vô vọng? (Feeling down, depressed, or hopeless?) | AR1: 3. Khó ngủ, ngủ không yên giấc hoặc ngủ quá nhiều? (Trouble falling or staying asleep, or sleeping too much?) | AS1: 4. Cảm thấy mệt mỏi hoặc không có năng lượng? (Feeling tired or having little energy?) | AT1: 5. Ăn không ngon hoặc ăn quá nhiều? (Poor appetite or overeating?) | AU1: 6. Cảm thấy tồi tệ về bản thân—hoặc cảm thấy mình là người thất bại hay đã làm gia đình thất vọng? (Feeling bad about yourself—or that you are a failure or have let yourself or your family down?) | AV1: 7. Gặp khó khăn trong việc tập trung vào mọi thứ, chẳng hạn như đọc báo hoặc xem tivi? (Trouble concentrating on things, such as reading the newspaper or watching television?) | AW1: 8. Di chuyển hoặc nói rất chậm chạp đến mức người khác có thể nhận thấy? Hoặc ngược lại—bồn chồn, không ngừng di chuyển, bồn chồn hơn bình thường? (Moving or speaking so slowly that other people could have noticed? Or the opposite—being so fidgety or restless that you have been moving around a lot more than usual?) | AX1: 9. Có suy nghĩ rằng mình sẽ chết đi thì tốt hơn hoặc có ý định tự làm hại bản thân theo cách nào đó? (Thoughts that you would be better off dead or of hurting yourself in some way?) | AY1: P_TOTAL | AZ1: PHQ9_RESULT | BA1: PHQ9_LABEL_10 | BB1: PHQ9_LABEL_14 | BC1: Trong 2 tuần qua, bạn đã bao nhiêu lần bị làm phiền bởi các vấn đề sau? 7 câu hỏi sau đây, lựa chọn theo mức độ mỗi câu: Không có - Vài ngày - Hơn một nửa số ngày - Gần như mỗi ngày 1. Cảm thấy lo lắng, bồn chồn hoặc căng thẳng | BD1: 2. Không thể ngừng hoặc kiểm soát sự lo lắng | BE1: 3. Lo lắng quá nhiều về nhiều thứ khác nhau | BF1: 4. Khó thư giãn | BG1: 5. Dễ bị khó chịu hoặc cáu kỉnh | BH1: 6. Quá bồn chồn đến mức khó có thể ngồi yên | BI1: 7. Cảm thấy sợ hãi như thể có điều gì đó khủng khiếp có thể xảy ra | BJ1: G_TOTAL | BK1: GAD7_RESULT | BL1: GAD7_LABEL_8 | BM1: GAD7_LABEL | BN1: Bạn có cảm thấy mập không? 1=Không bao giờ 2=Hiếm khi 3=Thỉnh thoảng 4=Thường xuyên 5=Luôn luôn | BO1: Bạn có cần phải rất gầy để cảm thấy tự tin về bản thân không? | BQ1: Tôi lo rằng mình sẽ không được người khác đối xử công bằng vì cân nặng của mình. ( 1=Hoàn toàn không đồng ý 2=Không đồng ý 3=Hơi không đồng ý 4=Hơi đồng ý 5=Đồng ý 6=Hoàn toàn đồng ý ) | BR1: Trong 4 tuần qua (28 ngày), bạn đã ăn một lượng thức ăn lớn bất thường trong bao nhiêu ngày và có cảm giác mất kiểm soát vào thời điểm đó? (Điền số 0-28) | BS1: Bạn có từng bị miệt thị ngoại hình (body shaming)? | BT1: bodyshaming_norm | BU1: Ai là người miệt thị ngoại hình (body shaming) bạn? | BV1: Bạn sẽ mô tả tình hình tài chính của mình như thế nào cho đúng? 1=Luôn căng thẳng 2=Thường xuyên căng thẳng 3=Thỉnh thoảng căng thẳng 4=Hiếm khi căng thẳng 5=Không bao giờ căng thẳng | BW1: Bạn có lo lắng gì về tình hình sống hiện tại của mình không, chẳng hạn như điều kiện nhà ở, an toàn và chi phí? | BX1: Tiền học phí của bạn là do ai chi trả: | BY1: Chi phí sinh hoạt có gây khó khăn đáng kể không? | BZ1: Bạn có cảm thấy bị áp lực khi nhìn thấy cuộc sống người khác trên mạng không? | CB1: Bạn có thường so sánh bản thân với người khác không? | CD1: Bạn thường xuyên cảm thấy mình thiếu bạn đồng hành đến mức nào? | CF1: Bạn thường cảm thấy bị bỏ rơi như thế nào? | CH1: Bạn thường cảm thấy bị cô lập với người khác như thế nào? | CJ1: Nền tảng bạn dùng nhiều nhất? | CK1: Bạn đã sử dụng các không gian trực tuyến như phương tiện truyền thông xã hội để tương tác với người khác về các vấn đề xã hội không? Vui lòng cho biết các loại vấn đề xã hội mà bạn đã tương tác bằng cách sử dụng các không gian trực tuyến | CL1: Trong tuần qua, trung bình mỗi ngày bạn dành khoảng bao nhiêu thời gian để sử dụng các không gian trực tuyến không dành cho việc học hoặc làm việc, chẳng hạn như mạng xã hội, chơi game, v.v. | CN1: Bạn có từng bị quấy rối online không? | CP1: Kể từ khi bạn bắt đầu đi học, bạn đã từng gặp phải những điều sau đây chưa? gồm 5 câu hỏi 1.Bị người khác làm tổn thương về thể chất (ví dụ: đánh, đẩy, xô sát)? | CQ1: 2.Bị lăng mạ, xúc phạm hoặc nói xấu? | CR1: 3.Bị đe dọa làm hại bạn hoặc người thân của bạn? | CS1: 4.Bị la hét, mắng chửi? | CT1: 5.Bị quấy rối hoặc bị chia sẻ thông tin cá nhân (tin nhắn, hình ảnh, video) mà không có sự đồng ý của bạn; hoặc bị yêu cầu/truy cập vào thông tin riêng tư? | CU1: ipv1 | CV1: ipv2 | CW1: ipv3 | CX1: ipv4 | CY1: ipv5 | CZ1: Trong năm qua, bạn có thể đã cố ý làm tổn thương bản thân, mà không có ý định tự tử. (Vd: Cắt, làm bỏng, đấm, đập, cào, cắn, cản trở quá trình lành vết thương, khắc chữ hoặc ký hiệu lên da, cọ xát vật sắc nhọn lên da để làm bản thân bị thương) | DB1: Trong năm qua, bạn có bao giờ nghĩ đến việc tự tử không? | DD1: Ý nghĩ, hành động tự tử bạn có gần nhất là cách đây mấy tuần? | DE1: Bạn có tham gia hoạt động thể dục/ thể thao không? | DG1: Bạn đã từng được chẩn đoán mắc bất kỳ tình trạng sức khỏe nào sau đây, cần điều trị liên tục bởi chuyên gia chăm sóc sức khỏe (tức là bệnh mãn tính) chưa? | DI1: Bạn đã từng được chuyên gia y tế chẩn đoán mắc bất kỳ tình trạng nào sau đây chưa? (ví dụ: bác sĩ chăm sóc sức khỏe ban đầu, bác sĩ tâm thần, nhà tâm lý học)? | DK1: Bạn đã từng nhận được tư vấn hoặc trị liệu cho các vấn đề về sức khỏe tâm thần chưa? | DM1: Tần suất tham gia / tuần | DO1: Bộ môn tham gia | DP1: Bạn đã từng là nạn nhân của hành vi xâm hại tình dục? | DQ1: xhtd_norm | DR1: Người thực hiện hành vi đó là | DS1: Bạn có sử dụng các app hẹn hò không? | DT1: Mục đích sử dụng app hẹn hò của bạn là gì? | DU1: Bạn hoặc người yêu (hiện tại hoặc cũ) của bạn đã từng mang thai chưa? | DV1: mangthai_norm | DW1: Bạn hoặc người yêu (hiện tại hoặc cũ) của bạn đã từng mang thai, vậy hướng xử lý như thế nào
A2: 46003.623 | B2: Đồng Nai | C2: Nam | D2: =if(C2="Nam", 0, 1) -> 0 | E2: Dị tính (Heterosexual) | F2: =IFERROR(__xludf.DUMMYFUNCTION("LET( t, LOWER(TRIM(E2)), IFS( REGEXMATCH(t,""chuyển giới|transgender""), 6, REGEXMATCH(t,""vô tính|asexual|nam nữ.*không có nhu cầu""), 4, REGEXMATCH(t,""toàn tính|pansexual""), 5, REGEXMATCH(t,""song tính|bisexual|biromantic""), 1, "&" AND(REGEXMATCH(t,""đồng tính nam|\bgay\b""), NOT(REGEXMATCH(t,""not gay|không gay|ko gay""))), 2, REGEXMATCH(t,""đồng tính nữ|\blesbian\b|em thích nữ|thích nữ|mê nữ|sapphic""), 3, REGEXMATCH(t,""^\.$|^(không|ko|k|no)$|^(không có|ko có)$""), 8, "&" REGEXMATCH(t,""không biết|chưa rõ|chưa xác định|ko hiểu|huh|strange|\?{3,}|hong có.*không biết|vn chỉ có nam và nữ""), 7, REGEXMATCH(t,""dị tính|heterosexual|thẳng|straight|khác giới|thích khác giới|trai gái|quan hệ trai gái|nam\s*-\s*nữ|nam\s*nữ|b"&"ình thường|normal|\bbth\b|\bbinh thuong\b|giới tính bình thường|xu hướng tính dục bth""), 0, TRUE, 7 ) )"),0.0) -> 0 | G2: Công giáo | H2: =IFERROR(__xludf.DUMMYFUNCTION("LET( t, LOWER(TRIM(G2)), IFS( REGEXMATCH(t,""phật giáo hòa hảo""), 3, REGEXMATCH(t,""công giáo""), 1, REGEXMATCH(t,""phật giáo""), 2, REGEXMATCH(t,""hồi giáo""), 4, REGEXMATCH(t,""cao đài|cao dai""), 5, REGEXMATCH(t,""bà la môn"&"|ba la mon""), 6, REGEXMATCH(t,""^kinh$""), 7, REGEXMATCH(t,""không tôn giáo|^(không|khong)$|^không có$|^khong co$|^không$|^không\s+$""), 0, TRUE, """" ) )"),1.0) -> 1 | I2: Thuê trọ | J2: =IFERROR(__xludf.DUMMYFUNCTION("LET( text, LOWER(I2), IFERROR( IFS( REGEXMATCH(text,""ở cùng gia đình|ở trọ cùng gia đình""), 0, REGEXMATCH(text,""thuê trọ""), 1, REGEXMATCH(text,""ở ktx""), 2, REGEXMATCH(text,""có nhà tại khu vực đang học|có nhà|ở riêng "&"tại chung cư""), 3, REGEXMATCH(text,""ở nhà người quen""), 4 ), -1) )"),1.0) -> 1 | K2: Khá | L2: =IFERROR(__xludf.DUMMYFUNCTION("LET( t, LOWER(TRIM(K2)), IFERROR( IFS( REGEXMATCH(t,""xuất\s*sắc""), 0, REGEXMATCH(t,""^giỏi$""), 1, REGEXMATCH(t,""^khá$""), 2, REGEXMATCH(t,""trung bình|bình thường|^4$""), 3, REGEXMATCH(t,""rớt""), 4, REGEXMA"&"TCH(t,""năm nhất|tân sinh viên|mới|chưa|không|sắp thi|chuẩn bị thi|kq|kết quả|chưa có|chưa biết""), 5, TRUE, 5 ), 5) )"),2.0) -> 2 | M2: Do xu hướng thị trường | N2: =IFERROR(__xludf.DUMMYFUNCTION("LET( t, LOWER(TRIM(M2)), IFERROR( IFS( REGEXMATCH(t,""ko biết|không biết|hơm bt|hôm bt|khum biết|chưa biết|không rõ|câu không rõ""), 3, REGEXMATCH(t,""50/50|bình thường|phân vân|lúc này lúc kia|fomo|đuối|hơi đuối|hơi không chắc""), 1,"&" REGEXMATCH(t,""không hợp|không phù hợp|hối hận|bất đắc dĩ|bất đắt dĩ|do không còn lựa chọn|không còn đam mê|mất đam mê|học không nổi""), 0, REGEXMATCH(t,""^có$|^có\b""), 0, REGEXMATCH(t,""^không$|^không\s|^không\.$|^không!$|^không,$|^"&"không\?$|phù hợp|siêu hợp|cảm thấy phù hợp|phù hợp rồi|ổn|ước mơ|tự chọn|năng lực|suy nghĩ""), 2, TRUE, 3 ), 3) )"),3.0) -> 3 | O2: Không | P2: =if(O2="Có", 1, 0) -> 0 | R2: =Q2 | V2: =IFERROR(__xludf.DUMMYFUNCTION("IFERROR(REGEXEXTRACT(U2,""\d+"")*1, """")"),"") | W2: =if(V2<>"", V2, 0) -> 0 | Z2: Không | AB2: Không | AC2: Không | AD2: Có một chút | AE2: Có một chút | AF2: Áp lực nhiều | AG2: Có chút ảnh hưởng | AH2: Có chút ảnh hưởng | AI2: Hiếm khi (1–2 lần) | AJ2: =LET( txt,LOWER(TRIM(SUBSTITUTE(AI2,CHAR(160)," "))), IFS( txt="không bao giờ",0, txt="hiếm khi (1–2 lần)",1, txt="thỉnh thoảng (vài lần)",2, txt="thường xuyên (thường xuyên trong vài tháng)",3, txt="luôn/rất thường xuyên",4, TRUE,"" ) ) -> 1 | AK2: Có chút ảnh hưởng | AL2: =LET( txt,LOWER(TRIM(SUBSTITUTE(AK2,CHAR(160)," "))), IFS( OR( ISNUMBER(SEARCH("không có trải nghiệm",txt)), ISNUMBER(SEARCH("chưa từng",txt)) ),-1, txt="không ảnh hưởng",0, ISNUMBER(SEARCH("có chút",txt)),1, AND(ISNUMBER(SEARCH("ảnh hưởng",txt)),ISNUMBER(SEARCH("rất",txt))),3, ISNUMBER(SEARCH("ảnh hưởng nhiều",txt)),2, TRUE,"" ) ) -> 1 | AM2: Độc thân | AN2: =LET( txt,LOWER(TRIM(AM2)), IFS( OR( txt="độc thân", txt="chưa có ny", txt="không có người yêu !!!!", txt="ế", txt="không có bồ", txt="không có", txt=".", txt="không có người yêu", txt="chưa yêu ai", txt="dạ chưa có mối tình đầu luôn ạ", txt="ko có người yêu", txt="đang kiếm phú bà nào đó ok ok", txt="án treo", txt="không", txt="ế quắt", txt="hiện tại không ai yêu và không quan tâm đến tình yêu", txt="0" ),0, txt="đã kết hôn",3, txt="trong mối quan hệ mập mờ",2, txt="có người yêu",1, TRUE,0 ) ) -> 0 | AP2: 2 | AQ2: 1 | AR2: 1 | AS2: 1 | AT2: 1 | AU2: 2 | AV2: 1 | AW2: 1 | AX2: 1 | AY2: =sum(AP2:AX2) -> 11 | AZ2: =AY2-9 -> 2 | BA2: =if(AZ2 >= 10 ,1,0) -> 0 | BB2: =if(AZ2 >= 14 ,1,0) -> 0 | BC2: 1 | BD2: 1 | BE2: 3 | BF2: 1 | BG2: 1 | BH2: 1 | BI2: 1 | BJ2: =sum(BC2:BI2) -> 9 | BK2: =BJ2-7 -> 2 | BN2: 2 | BO2: Không | BP2: =if(BO2="Không",0,1) -> 0 | BQ2: 2 | BR2: 0 | BS2: Không | BT2: =if(BS2="Không",0,1) -> 0 | BV2: 3 | BW2: Không | BX2: Cha mẹ | BY2: Không | BZ2: Có một chút | CA2: =LET( txt,LOWER(TRIM(SUBSTITUTE(BZ2,CHAR(160)," "))), IFS( ISNUMBER(SEARCH("không",txt)),0, ISNUMBER(SEARCH("có một chút",txt)),1, ISNUMBER(SEARCH("thường xuyên",txt)),2, TRUE,"" ) ) -> 1 | CB2: Có một chút | CC2: =LET( txt,LOWER(TRIM(SUBSTITUTE(CB2,CHAR(160)," "))), IFS( ISNUMBER(SEARCH("không",txt)),0, ISNUMBER(SEARCH("có một chút",txt)),1, ISNUMBER(SEARCH("thường xuyên",txt)),2, TRUE,"" ) ) -> 1 | CD2: Hiếm khi | CE2: =LET( txt,LOWER(TRIM(SUBSTITUTE(CD2,CHAR(160)," "))), IFS( ISNUMBER(SEARCH("hiếm khi",txt)),0, ISNUMBER(SEARCH("thỉnh thoảng",txt)),1, ISNUMBER(SEARCH("thường xuyên",txt)),2, TRUE,"" ) ) -> 0 | CF2: Hiếm khi | CG2: =LET( txt,LOWER(TRIM(SUBSTITUTE(CF2,CHAR(160)," "))), IFS( ISNUMBER(SEARCH("hiếm khi",txt)),0, ISNUMBER(SEARCH("thỉnh thoảng",txt)),1, ISNUMBER(SEARCH("thường xuyên",txt)),2, TRUE,"" ) ) -> 0 | CH2: Hiếm khi | CI2: =LET( txt,LOWER(TRIM(SUBSTITUTE(CH2,CHAR(160)," "))), IFS( ISNUMBER(SEARCH("hiếm khi",txt)),0, ISNUMBER(SEARCH("thỉnh thoảng",txt)),1, ISNUMBER(SEARCH("thường xuyên",txt)),2, TRUE,"" ) ) -> 0 | CJ2: Game | CK2: Không | CL2: 3-4 giờ mỗi ngày | CM2: =IFS( ISNUMBER(SEARCH("10-30",CL2)),0.33, ISNUMBER(SEARCH("31-60",CL2)),0.75, ISNUMBER(SEARCH("1-2",CL2)),1.5, ISNUMBER(SEARCH("3-4",CL2)),3.5, ISNUMBER(SEARCH("Hơn 5",CL2)),6, ISNUMBER(SEARCH("9 giờ",CL2)),9, ISNUMBER(SEARCH("18",CL2)),18, ISNUMBER(SEARCH("Không có",CL2)),0, ISNUMBER(SEARCH("Cả ngày",CL2)),18, ISNUMBER(SEARCH("Mọi lúc",CL2)),18, ISNUMBER(SEARCH("Hàng giờ",CL2)),12, ISNUMBER(SEARCH("không cố định",LOWER(CL2))),NA(), ISNUMBER(SEARCH("không theo",LOWER(CL2))),NA(), ISNUMBER(SEARCH("tranh thủ",LOWER(CL2))),NA(), ISNUMBER(SEARCH("tùy",LOWER(CL2))),NA(), ISNUMBER(SEARCH("sau 10h",LOWER(CL2))),2, TRUE,NA() ) -> 3.5 | CN2: Không | CO2: =if(CN2="Không", 0, if(CN2="Nhiều", 2, 1)) -> 0 | CP2: Không | CQ2: Không | CR2: Không | CS2: Không | CT2: Không | CU2: =if(CP2="Không",0,1) -> 0 | CV2: =if(CQ2="Không",0,1) -> 0 | CW2: =if(CR2="Không",0,1) -> 0 | CX2: =if(CS2="Không",0,1) -> 0 | CY2: =if(CT2="Không",0,1) -> 0 | CZ2: Không | DA2: =if(CZ2="Không",0,1) -> 0 | DB2: Không | DC2: =if(DB2="Không",0,1) -> 0 | DE2: Có | DF2: =if(DE2="Có", 1, 0) -> 1 | DG2: Không có | DH2: =if(DG2="Không có", 0, 1) -> 0 | DI2: Không | DJ2: =if(DI2="Không", 0, 1) -> 0 | DK2: Không, không bao giờ | DL2: =IFS( ISNUMBER(SEARCH("không",LOWER(DK2))),0, ISNUMBER(SEARCH("chưa",LOWER(DK2))),0, ISNUMBER(SEARCH("cả hai",LOWER(DK2))),3, AND(ISNUMBER(SEARCH("trước",LOWER(DK2))),ISNUMBER(SEARCH("đại học",LOWER(DK2)))),1, AND(ISNUMBER(SEARCH("kể từ khi",LOWER(DK2))),ISNUMBER(SEARCH("đại học",LOWER(DK2)))),2, ISNUMBER(SEARCH("thuốc",LOWER(DK2))),2, ISNUMBER(SEARCH("bác sĩ",LOWER(DK2))),2, TRUE,NA() ) -> 0 | DM2: 1-2 giờ | DN2: =LET( x,LOWER(TRIM(DM2)), IF(OR(x="không",x="0",x="hồi đó giờ ko chơi",x="hồi đó giờ không chơi"),0, IF(ISNUMBER(SEARCH("dưới 1",x)),0.5, IF(ISNUMBER(SEARCH("5 giờ trở lên",x)),5, IF(ISNUMBER(SEARCH("mỗi ngày",x)), IF(ISNUMBER(SEARCH("mỗi ngày ",x)), VALUE(MID(x,SEARCH("mỗi ngày ",x)+9,SEARCH(" giờ",x)-SEARCH("mỗi ngày ",x)-9))*7, VALUE(LEFT(x,SEARCH(" giờ",x)-1))*7 ), IF(ISNUMBER(SEARCH("-",x)), (VALUE(LEFT(x,SEARCH("-",x)-1))+VALUE(MID(x,SEARCH("-",x)+1,SEARCH(" giờ",x)-SEARCH("-",x)-1)))/2, IF(ISNUMBER(SEARCH(" giờ",x)), VALUE(LEFT(x,SEARCH(" giờ",x)-1)), "")))))) ) -> 1.5 | DO2: Chạy bộ | DP2: Không | DQ2: =IF(DP2 = "Không", 0, 1) -> 0 | DS2: Không | DU2: Không
A3: 46003.626 | B3: Quảng Bình | C3: Nam | D3: =if(C3="Nam", 0, 1) -> 0 | E3: Dị tính (Heterosexual) | F3: =IFERROR(__xludf.DUMMYFUNCTION("LET( t, LOWER(TRIM(E3)), IFS( REGEXMATCH(t,""chuyển giới|transgender""), 6, REGEXMATCH(t,""vô tính|asexual|nam nữ.*không có nhu cầu""), 4, REGEXMATCH(t,""toàn tính|pansexual""), 5, REGEXMATCH(t,""song tính|bisexual|biromantic""), 1, "&" AND(REGEXMATCH(t,""đồng tính nam|\bgay\b""), NOT(REGEXMATCH(t,""not gay|không gay|ko gay""))), 2, REGEXMATCH(t,""đồng tính nữ|\blesbian\b|em thích nữ|thích nữ|mê nữ|sapphic""), 3, REGEXMATCH(t,""^\.$|^(không|ko|k|no)$|^(không có|ko có)$""), 8, "&" REGEXMATCH(t,""không biết|chưa rõ|chưa xác định|ko hiểu|huh|strange|\?{3,}|hong có.*không biết|vn chỉ có nam và nữ""), 7, REGEXMATCH(t,""dị tính|heterosexual|thẳng|straight|khác giới|thích khác giới|trai gái|quan hệ trai gái|nam\s*-\s*nữ|nam\s*nữ|b"&"ình thường|normal|\bbth\b|\bbinh thuong\b|giới tính bình thường|xu hướng tính dục bth""), 0, TRUE, 7 ) )"),0.0) -> 0 | G3: Công giáo | H3: =IFERROR(__xludf.DUMMYFUNCTION("LET( t, LOWER(TRIM(G3)), IFS( REGEXMATCH(t,""phật giáo hòa hảo""), 3, REGEXMATCH(t,""công giáo""), 1, REGEXMATCH(t,""phật giáo""), 2, REGEXMATCH(t,""hồi giáo""), 4, REGEXMATCH(t,""cao đài|cao dai""), 5, REGEXMATCH(t,""bà la môn"&"|ba la mon""), 6, REGEXMATCH(t,""^kinh$""), 7, REGEXMATCH(t,""không tôn giáo|^(không|khong)$|^không có$|^khong co$|^không$|^không\s+$""), 0, TRUE, """" ) )"),1.0) -> 1 | I3: Có nhà tại khu vực đang học | J3: =IFERROR(__xludf.DUMMYFUNCTION("LET( text, LOWER(I3), IFERROR( IFS( REGEXMATCH(text,""ở cùng gia đình|ở trọ cùng gia đình""), 0, REGEXMATCH(text,""thuê trọ""), 1, REGEXMATCH(text,""ở ktx""), 2, REGEXMATCH(text,""có nhà tại khu vực đang học|có nhà|ở riêng "&"tại chung cư""), 3, REGEXMATCH(text,""ở nhà người quen""), 4 ), -1) )"),3.0) -> 3 | K3: Trung bình | L3: =IFERROR(__xludf.DUMMYFUNCTION("LET( t, LOWER(TRIM(K3)), IFERROR( IFS( REGEXMATCH(t,""xuất\s*sắc""), 0, REGEXMATCH(t,""^giỏi$""), 1, REGEXMATCH(t,""^khá$""), 2, REGEXMATCH(t,""trung bình|bình thường|^4$""), 3, REGEXMATCH(t,""rớt""), 4, REGEXMA"&"TCH(t,""năm nhất|tân sinh viên|mới|chưa|không|sắp thi|chuẩn bị thi|kq|kết quả|chưa có|chưa biết""), 5, TRUE, 5 ), 5) )"),3.0) -> 3 | M3: Do xu hướng thị trường | N3: =IFERROR(__xludf.DUMMYFUNCTION("LET( t, LOWER(TRIM(M3)), IFERROR( IFS( REGEXMATCH(t,""ko biết|không biết|hơm bt|hôm bt|khum biết|chưa biết|không rõ|câu không rõ""), 3, REGEXMATCH(t,""50/50|bình thường|phân vân|lúc này lúc kia|fomo|đuối|hơi đuối|hơi không chắc""), 1,"&" REGEXMATCH(t,""không hợp|không phù hợp|hối hận|bất đắc dĩ|bất đắt dĩ|do không còn lựa chọn|không còn đam mê|mất đam mê|học không nổi""), 0, REGEXMATCH(t,""^có$|^có\b""), 0, REGEXMATCH(t,""^không$|^không\s|^không\.$|^không!$|^không,$|^"&"không\?$|phù hợp|siêu hợp|cảm thấy phù hợp|phù hợp rồi|ổn|ước mơ|tự chọn|năng lực|suy nghĩ""), 2, TRUE, 3 ), 3) )"),3.0) -> 3 | O3: Có | P3: =if(O3="Có", 1, 0) -> 1 | Q3: 1 | R3: =Q3 -> 1 | S3: Việc liên quan đến chuyên ngành | U3: <=15h/ tuần, | V3: =IFERROR(__xludf.DUMMYFUNCTION("IFERROR(REGEXEXTRACT(U3,""\d+"")*1, """")"),15.0) -> 15 | W3: =if(V3<>"", V3, 0) -> 15 | X3: 1 | Y3: 0 | Z3: Không | AB3: Không | AC3: Không | AD3: Rất lo lắng | AE3: Không | AF3: Có chút áp lực | AG3: Có chút ảnh hưởng | AH3: Có chút ảnh hưởng | AI3: Hiếm khi (1–2 lần) | AJ3: =LET( txt,LOWER(TRIM(SUBSTITUTE(AI3,CHAR(160)," "))), IFS( txt="không bao giờ",0, txt="hiếm khi (1–2 lần)",1, txt="thỉnh thoảng (vài lần)",2, txt="thường xuyên (thường xuyên trong vài tháng)",3, txt="luôn/rất thường xuyên",4, TRUE,"" ) ) -> 1 | AK3: Có chút ảnh hưởng | AL3: =LET( txt,LOWER(TRIM(SUBSTITUTE(AK3,CHAR(160)," "))), IFS( OR( ISNUMBER(SEARCH("không có trải nghiệm",txt)), ISNUMBER(SEARCH("chưa từng",txt)) ),-1, txt="không ảnh hưởng",0, ISNUMBER(SEARCH("có chút",txt)),1, AND(ISNUMBER(SEARCH("ảnh hưởng",txt)),ISNUMBER(SEARCH("rất",txt))),3, ISNUMBER(SEARCH("ảnh hưởng nhiều",txt)),2, TRUE,"" ) ) -> 1 | AM3: Độc thân | AN3: =LET( txt,LOWER(TRIM(AM3)), IFS( OR( txt="độc thân", txt="chưa có ny", txt="không có người yêu !!!!", txt="ế", txt="không có bồ", txt="không có", txt=".", txt="không có người yêu", txt="chưa yêu ai", txt="dạ chưa có mối tình đầu luôn ạ", txt="ko có người yêu", txt="đang kiếm phú bà nào đó ok ok", txt="án treo", txt="không", txt="ế quắt", txt="hiện tại không ai yêu và không quan tâm đến tình yêu", txt="0" ),0, txt="đã kết hôn",3, txt="trong mối quan hệ mập mờ",2, txt="có người yêu",1, TRUE,0 ) ) -> 0 | AP3: 1 | AQ3: 3 | AR3: 2 | AS3: 2 | AT3: 2 | AU3: 3 | AV3: 2 | AW3: 2 | AX3: 2 | AY3: =sum(AP3:AX3) -> 19 | AZ3: =AY3-9 -> 10 | BA3: =if(AZ3 >= 10 ,1,0) -> 1 | BB3: =if(AZ3 >= 14 ,1,0) -> 0 | BC3: 2 | BD3: 2 | BE3: 3 | BF3: 3 | BG3: 2 | BH3: 3 | BI3: 1 | BJ3: =sum(BC3:BI3) -> 16 | BK3: =BJ3-7 -> 9 | BN3: 2 | BO3: Không | BP3: =if(BO3="Không",0,1) -> 0 | BQ3: 3 | BR3: 10 | BS3: Có | BT3: =if(BS3="Không",0,1) -> 1 | BU3: Bạn bè | BV3: 2 | BW3: Có | BX3: Cha mẹ | BY3: Có | BZ3: Có một chút | CA3: =LET( txt,LOWER(TRIM(SUBSTITUTE(BZ3,CHAR(160)," "))), IFS( ISNUMBER(SEARCH("không",txt)),0, ISNUMBER(SEARCH("có một chút",txt)),1, ISNUMBER(SEARCH("thường xuyên",txt)),2, TRUE,"" ) ) -> 1 | CB3: Có một chút | CC3: =LET( txt,LOWER(TRIM(SUBSTITUTE(CB3,CHAR(160)," "))), IFS( ISNUMBER(SEARCH("không",txt)),0, ISNUMBER(SEARCH("có một chút",txt)),1, ISNUMBER(SEARCH("thường xuyên",txt)),2, TRUE,"" ) ) -> 1 | CD3: Thường xuyên | CE3: =LET( txt,LOWER(TRIM(SUBSTITUTE(CD3,CHAR(160)," "))), IFS( ISNUMBER(SEARCH("hiếm khi",txt)),0, ISNUMBER(SEARCH("thỉnh thoảng",txt)),1, ISNUMBER(SEARCH("thường xuyên",txt)),2, TRUE,"" ) ) -> 2 | CF3: Thỉnh thoảng | CG3: =LET( txt,LOWER(TRIM(SUBSTITUTE(CF3,CHAR(160)," "))), IFS( ISNUMBER(SEARCH("hiếm khi",txt)),0, ISNUMBER(SEARCH("thỉnh thoảng",txt)),1, ISNUMBER(SEARCH("thường xuyên",txt)),2, TRUE,"" ) ) -> 1 | CH3: Thường xuyên | CI3: =LET( txt,LOWER(TRIM(SUBSTITUTE(CH3,CHAR(160)," "))), IFS( ISNUMBER(SEARCH("hiếm khi",txt)),0, ISNUMBER(SEARCH("thỉnh thoảng",txt)),1, ISNUMBER(SEARCH("thường xuyên",txt)),2, TRUE,"" ) ) -> 2 | CJ3: Instagram | CK3: Các chủ đề chính trị | CL3: Hơn 5 giờ mỗi ngày | CM3: =IFS( ISNUMBER(SEARCH("10-30",CL3)),0.33, ISNUMBER(SEARCH("31-60",CL3)),0.75, ISNUMBER(SEARCH("1-2",CL3)),1.5, ISNUMBER(SEARCH("3-4",CL3)),3.5, ISNUMBER(SEARCH("Hơn 5",CL3)),6, ISNUMBER(SEARCH("9 giờ",CL3)),9, ISNUMBER(SEARCH("18",CL3)),18, ISNUMBER(SEARCH("Không có",CL3)),0, ISNUMBER(SEARCH("Cả ngày",CL3)),18, ISNUMBER(SEARCH("Mọi lúc",CL3)),18, ISNUMBER(SEARCH("Hàng giờ",CL3)),12, ISNUMBER(SEARCH("không cố định",LOWER(CL3))),NA(), ISNUMBER(SEARCH("không theo",LOWER(CL3))),NA(), ISNUMBER(SEARCH("tranh thủ",LOWER(CL3))),NA(), ISNUMBER(SEARCH("tùy",LOWER(CL3))),NA(), ISNUMBER(SEARCH("sau 10h",LOWER(CL3))),2, TRUE,NA() ) -> 6 | CN3: Có thỉnh thoảng | CO3: =if(CN3="Không", 0, if(CN3="Nhiều", 2, 1)) -> 1 | CP3: Có | CQ3: Có | CR3: Có | CS3: Không | CT3: Không | CU3: =if(CP3="Không",0,1) -> 1 | CV3: =if(CQ3="Không",0,1) -> 1 | CW3: =if(CR3="Không",0,1) -> 1 | CX3: =if(CS3="Không",0,1) -> 0 | CY3: =if(CT3="Không",0,1) -> 0 | CZ3: Không | DA3: =if(CZ3="Không",0,1) -> 0 | DB3: Không | DC3: =if(DB3="Không",0,1) -> 0 | DE3: Có | DF3: =if(DE3="Có", 1, 0) -> 1 | DG3: Hen suyễn | DH3: =if(DG3="Không có", 0, 1) -> 1 | DI3: ADHD | DJ3: =if(DI3="Không", 0, 1) -> 1 | DK3: Không, không bao giờ | DL3: =IFS( ISNUMBER(SEARCH("không",LOWER(DK3))),0, ISNUMBER(SEARCH("chưa",LOWER(DK3))),0, ISNUMBER(SEARCH("cả hai",LOWER(DK3))),3, AND(ISNUMBER(SEARCH("trước",LOWER(DK3))),ISNUMBER(SEARCH("đại học",LOWER(DK3)))),1, AND(ISNUMBER(SEARCH("kể từ khi",LOWER(DK3))),ISNUMBER(SEARCH("đại học",LOWER(DK3)))),2, ISNUMBER(SEARCH("thuốc",LOWER(DK3))),2, ISNUMBER(SEARCH("bác sĩ",LOWER(DK3))),2, TRUE,NA() ) -> 0 | DM3: 3-4 giờ | DN3: =LET( x,LOWER(TRIM(DM3)), IF(OR(x="không",x="0",x="hồi đó giờ ko chơi",x="hồi đó giờ không chơi"),0, IF(ISNUMBER(SEARCH("dưới 1",x)),0.5, IF(ISNUMBER(SEARCH("5 giờ trở lên",x)),5, IF(ISNUMBER(SEARCH("mỗi ngày",x)), IF(ISNUMBER(SEARCH("mỗi ngày ",x)), VALUE(MID(x,SEARCH("mỗi ngày ",x)+9,SEARCH(" giờ",x)-SEARCH("mỗi ngày ",x)-9))*7, VALUE(LEFT(x,SEARCH(" giờ",x)-1))*7 ), IF(ISNUMBER(SEARCH("-",x)), (VALUE(LEFT(x,SEARCH("-",x)-1))+VALUE(MID(x,SEARCH("-",x)+1,SEARCH(" giờ",x)-SEARCH("-",x)-1)))/2, IF(ISNUMBER(SEARCH(" giờ",x)), VALUE(LEFT(x,SEARCH(" giờ",x)-1)), "")))))) ) -> 3.5 | DO3: Bóng đá | DP3: Không | DQ3: =IF(DP3 = "Không", 0, 1) -> 0 | DS3: Có | DT3: Friend With Benefits | DU3: Không
A4: 46003.626 | B4: TP. Hồ Chí Minh | C4: Nam | D4: =if(C4="Nam", 0, 1) -> 0 | E4: Dị tính (Heterosexual) | F4: =IFERROR(__xludf.DUMMYFUNCTION("LET( t, LOWER(TRIM(E4)), IFS( REGEXMATCH(t,""chuyển giới|transgender""), 6, REGEXMATCH(t,""vô tính|asexual|nam nữ.*không có nhu cầu""), 4, REGEXMATCH(t,""toàn tính|pansexual""), 5, REGEXMATCH(t,""song tính|bisexual|biromantic""), 1, "&" AND(REGEXMATCH(t,""đồng tính nam|\bgay\b""), NOT(REGEXMATCH(t,""not gay|không gay|ko gay""))), 2, REGEXMATCH(t,""đồng tính nữ|\blesbian\b|em thích nữ|thích nữ|mê nữ|sapphic""), 3, REGEXMATCH(t,""^\.$|^(không|ko|k|no)$|^(không có|ko có)$""), 8, "&" REGEXMATCH(t,""không biết|chưa rõ|chưa xác định|ko hiểu|huh|strange|\?{3,}|hong có.*không biết|vn chỉ có nam và nữ""), 7, REGEXMATCH(t,""dị tính|heterosexual|thẳng|straight|khác giới|thích khác giới|trai gái|quan hệ trai gái|nam\s*-\s*nữ|nam\s*nữ|b"&"ình thường|normal|\bbth\b|\bbinh thuong\b|giới tính bình thường|xu hướng tính dục bth""), 0, TRUE, 7 ) )"),0.0) -> 0 | G4: Phật giáo | H4: =IFERROR(__xludf.DUMMYFUNCTION("LET( t, LOWER(TRIM(G4)), IFS( REGEXMATCH(t,""phật giáo hòa hảo""), 3, REGEXMATCH(t,""công giáo""), 1, REGEXMATCH(t,""phật giáo""), 2, REGEXMATCH(t,""hồi giáo""), 4, REGEXMATCH(t,""cao đài|cao dai""), 5, REGEXMATCH(t,""bà la môn"&"|ba la mon""), 6, REGEXMATCH(t,""^kinh$""), 7, REGEXMATCH(t,""không tôn giáo|^(không|khong)$|^không có$|^khong co$|^không$|^không\s+$""), 0, TRUE, """" ) )"),2.0) -> 2 | I4: Thuê trọ | J4: =IFERROR(__xludf.DUMMYFUNCTION("LET( text, LOWER(I4), IFERROR( IFS( REGEXMATCH(text,""ở cùng gia đình|ở trọ cùng gia đình""), 0, REGEXMATCH(text,""thuê trọ""), 1, REGEXMATCH(text,""ở ktx""), 2, REGEXMATCH(text,""có nhà tại khu vực đang học|có nhà|ở riêng "&"tại chung cư""), 3, REGEXMATCH(text,""ở nhà người quen""), 4 ), -1) )"),1.0) -> 1 | K4: Giỏi | L4: =IFERROR(__xludf.DUMMYFUNCTION("LET( t, LOWER(TRIM(K4)), IFERROR( IFS( REGEXMATCH(t,""xuất\s*sắc""), 0, REGEXMATCH(t,""^giỏi$""), 1, REGEXMATCH(t,""^khá$""), 2, REGEXMATCH(t,""trung bình|bình thường|^4$""), 3, REGEXMATCH(t,""rớt""), 4, REGEXMA"&"TCH(t,""năm nhất|tân sinh viên|mới|chưa|không|sắp thi|chuẩn bị thi|kq|kết quả|chưa có|chưa biết""), 5, TRUE, 5 ), 5) )"),1.0) -> 1 | M4: Tự chọn | N4: =IFERROR(__xludf.DUMMYFUNCTION("LET( t, LOWER(TRIM(M4)), IFERROR( IFS( REGEXMATCH(t,""ko biết|không biết|hơm bt|hôm bt|khum biết|chưa biết|không rõ|câu không rõ""), 3, REGEXMATCH(t,""50/50|bình thường|phân vân|lúc này lúc kia|fomo|đuối|hơi đuối|hơi không chắc""), 1,"&" REGEXMATCH(t,""không hợp|không phù hợp|hối hận|bất đắc dĩ|bất đắt dĩ|do không còn lựa chọn|không còn đam mê|mất đam mê|học không nổi""), 0, REGEXMATCH(t,""^có$|^có\b""), 0, REGEXMATCH(t,""^không$|^không\s|^không\.$|^không!$|^không,$|^"&"không\?$|phù hợp|siêu hợp|cảm thấy phù hợp|phù hợp rồi|ổn|ước mơ|tự chọn|năng lực|suy nghĩ""), 2, TRUE, 3 ), 3) )"),2.0) -> 2 | O4: Có | P4: =if(O4="Có", 1, 0) -> 1 | Q4: 1 | R4: =Q4 -> 1 | S4: Nhân viên phục vụ, bán hàng | U4: <=25h/ tuần | V4: =IFERROR(__xludf.DUMMYFUNCTION("IFERROR(REGEXEXTRACT(U4,""\d+"")*1, """")"),25.0) -> 25 | W4: =if(V4<>"", V4, 0) -> 25 | X4: 10 | Y4: 0 | Z4: Có một chút | AB4: Không | AC4: Không | AD4: Rất lo lắng | AE4: Nhiều | AF4: Có chút áp lực | AG4: Ảnh hưởng nhiều | AH4: Có chút ảnh hưởng | AI4: Thỉnh thoảng (vài lần) | AJ4: =LET( txt,LOWER(TRIM(SUBSTITUTE(AI4,CHAR(160)," "))), IFS( txt="không bao giờ",0, txt="hiếm khi (1–2 lần)",1, txt="thỉnh thoảng (vài lần)",2, txt="thường xuyên (thường xuyên trong vài tháng)",3, txt="luôn/rất thường xuyên",4, TRUE,"" ) ) -> 2 | AK4: Ảnh hưởng nhiều | AL4: =LET( txt,LOWER(TRIM(SUBSTITUTE(AK4,CHAR(160)," "))), IFS( OR( ISNUMBER(SEARCH("không có trải nghiệm",txt)), ISNUMBER(SEARCH("chưa từng",txt)) ),-1, txt="không ảnh hưởng",0, ISNUMBER(SEARCH("có chút",txt)),1, AND(ISNUMBER(SEARCH("ảnh hưởng",txt)),ISNUMBER(SEARCH("rất",txt))),3, ISNUMBER(SEARCH("ảnh hưởng nhiều",txt)),2, TRUE,"" ) ) -> 2 | AM4: Có người yêu | AN4: =LET( txt,LOWER(TRIM(AM4)), IFS( OR( txt="độc thân", txt="chưa có ny", txt="không có người yêu !!!!", txt="ế", txt="không có bồ", txt="không có", txt=".", txt="không có người yêu", txt="chưa yêu ai", txt="dạ chưa có mối tình đầu luôn ạ", txt="ko có người yêu", txt="đang kiếm phú bà nào đó ok ok", txt="án treo", txt="không", txt="ế quắt", txt="hiện tại không ai yêu và không quan tâm đến tình yêu", txt="0" ),0, txt="đã kết hôn",3, txt="trong mối quan hệ mập mờ",2, txt="có người yêu",1, TRUE,0 ) ) -> 1 | AP4: 4 | AQ4: 4 | AR4: 4 | AS4: 4 | AT4: 4 | AU4: 4 | AV4: 4 | AW4: 4 | AX4: 4 | AY4: =sum(AP4:AX4) -> 36 | AZ4: =AY4-9 -> 27 | BA4: =if(AZ4 >= 10 ,1,0) -> 1 | BB4: =if(AZ4 >= 14 ,1,0) -> 1 | BC4: 4 | BD4: 4 | BE4: 4 | BF4: 4 | BG4: 4 | BH4: 4 | BI4: 4 | BJ4: =sum(BC4:BI4) -> 28 | BK4: =BJ4-7 -> 21 | BN4: 3 | BO4: Không | BP4: =if(BO4="Không",0,1) -> 0 | BQ4: 3 | BR4: 0 | BS4: Không | BT4: =if(BS4="Không",0,1) -> 0 | BV4: 3 | BW4: Có | BX4: Cha mẹ | BY4: Có | BZ4: Có một chút | CA4: =LET( txt,LOWER(TRIM(SUBSTITUTE(BZ4,CHAR(160)," "))), IFS( ISNUMBER(SEARCH("không",txt)),0, ISNUMBER(SEARCH("có một chút",txt)),1, ISNUMBER(SEARCH("thường xuyên",txt)),2, TRUE,"" ) ) -> 1 | CB4: Có một chút | CC4: =LET( txt,LOWER(TRIM(SUBSTITUTE(CB4,CHAR(160)," "))), IFS( ISNUMBER(SEARCH("không",txt)),0, ISNUMBER(SEARCH("có một chút",txt)),1, ISNUMBER(SEARCH("thường xuyên",txt)),2, TRUE,"" ) ) -> 1 | CD4: Thỉnh thoảng | CE4: =LET( txt,LOWER(TRIM(SUBSTITUTE(CD4,CHAR(160)," "))), IFS( ISNUMBER(SEARCH("hiếm khi",txt)),0, ISNUMBER(SEARCH("thỉnh thoảng",txt)),1, ISNUMBER(SEARCH("thường xuyên",txt)),2, TRUE,"" ) ) -> 1 | CF4: Thỉnh thoảng | CG4: =LET( txt,LOWER(TRIM(SUBSTITUTE(CF4,CHAR(160)," "))), IFS( ISNUMBER(SEARCH("hiếm khi",txt)),0, ISNUMBER(SEARCH("thỉnh thoảng",txt)),1, ISNUMBER(SEARCH("thường xuyên",txt)),2, TRUE,"" ) ) -> 1 | CH4: Thỉnh thoảng | CI4: =LET( txt,LOWER(TRIM(SUBSTITUTE(CH4,CHAR(160)," "))), IFS( ISNUMBER(SEARCH("hiếm khi",txt)),0, ISNUMBER(SEARCH("thỉnh thoảng",txt)),1, ISNUMBER(SEARCH("thường xuyên",txt)),2, TRUE,"" ) ) -> 1 | CJ4: TikTok | CK4: Phân biệt đối xử dựa trên bản dạng xã hội, Sức khỏe thể chất, tinh thần, tình dục hoặc các hình thức khác, Các vấn đề liên quan đến tâm linh, tôn giáo hoặc văn hóa, Các chủ đề về môi trường | CL4: 31-60 phút mỗi ngày | CM4: =IFS( ISNUMBER(SEARCH("10-30",CL4)),0.33, ISNUMBER(SEARCH("31-60",CL4)),0.75, ISNUMBER(SEARCH("1-2",CL4)),1.5, ISNUMBER(SEARCH("3-4",CL4)),3.5, ISNUMBER(SEARCH("Hơn 5",CL4)),6, ISNUMBER(SEARCH("9 giờ",CL4)),9, ISNUMBER(SEARCH("18",CL4)),18, ISNUMBER(SEARCH("Không có",CL4)),0, ISNUMBER(SEARCH("Cả ngày",CL4)),18, ISNUMBER(SEARCH("Mọi lúc",CL4)),18, ISNUMBER(SEARCH("Hàng giờ",CL4)),12, ISNUMBER(SEARCH("không cố định",LOWER(CL4))),NA(), ISNUMBER(SEARCH("không theo",LOWER(CL4))),NA(), ISNUMBER(SEARCH("tranh thủ",LOWER(CL4))),NA(), ISNUMBER(SEARCH("tùy",LOWER(CL4))),NA(), ISNUMBER(SEARCH("sau 10h",LOWER(CL4))),2, TRUE,NA() ) -> 0.75 | CN4: Có thỉnh thoảng | CO4: =if(CN4="Không", 0, if(CN4="Nhiều", 2, 1)) -> 1 | CP4: Không | CQ4: Không | CR4: Không | CS4: Không | CT4: Không | CU4: =if(CP4="Không",0,1) -> 0 | CV4: =if(CQ4="Không",0,1) -> 0 | CW4: =if(CR4="Không",0,1) -> 0 | CX4: =if(CS4="Không",0,1) -> 0 | CY4: =if(CT4="Không",0,1) -> 0 | CZ4: Không | DA4: =if(CZ4="Không",0,1) -> 0 | DB4: Không | DC4: =if(DB4="Không",0,1) -> 0 | DE4: Có | DF4: =if(DE4="Có", 1, 0) -> 1 | DG4: Không có | DH4: =if(DG4="Không có", 0, 1) -> 0 | DI4: Không | DJ4: =if(DI4="Không", 0, 1) -> 0 | DK4: Không, không bao giờ | DL4: =IFS( ISNUMBER(SEARCH("không",LOWER(DK4))),0, ISNUMBER(SEARCH("chưa",LOWER(DK4))),0, ISNUMBER(SEARCH("cả hai",LOWER(DK4))),3, AND(ISNUMBER(SEARCH("trước",LOWER(DK4))),ISNUMBER(SEARCH("đại học",LOWER(DK4)))),1, AND(ISNUMBER(SEARCH("kể từ khi",LOWER(DK4))),ISNUMBER(SEARCH("đại học",LOWER(DK4)))),2, ISNUMBER(SEARCH("thuốc",LOWER(DK4))),2, ISNUMBER(SEARCH("bác sĩ",LOWER(DK4))),2, TRUE,NA() ) -> 0 | DM4: 2-3 giờ | DN4: =LET( x,LOWER(TRIM(DM4)), IF(OR(x="không",x="0",x="hồi đó giờ ko chơi",x="hồi đó giờ không chơi"),0, IF(ISNUMBER(SEARCH("dưới 1",x)),0.5, IF(ISNUMBER(SEARCH("5 giờ trở lên",x)),5, IF(ISNUMBER(SEARCH("mỗi ngày",x)), IF(ISNUMBER(SEARCH("mỗi ngày ",x)), VALUE(MID(x,SEARCH("mỗi ngày ",x)+9,SEARCH(" giờ",x)-SEARCH("mỗi ngày ",x)-9))*7, VALUE(LEFT(x,SEARCH(" giờ",x)-1))*7 ), IF(ISNUMBER(SEARCH("-",x)), (VALUE(LEFT(x,SEARCH("-",x)-1))+VALUE(MID(x,SEARCH("-",x)+1,SEARCH(" giờ",x)-SEARCH("-",x)-1)))/2, IF(ISNUMBER(SEARCH(" giờ",x)), VALUE(LEFT(x,SEARCH(" giờ",x)-1)), "")))))) ) -> 2.5 | DO4: Chạy bộ, Đi bộ, Võ | DP4: Không | DQ4: =IF(DP4 = "Không", 0, 1) -> 0 | DS4: Không | DU4: Không
A5: 46003.626 | B5: Bà Rịa-Vũng Tàu | C5: Nam | D5: =if(C5="Nam", 0, 1) -> 0 | E5: bình thường | F5: =IFERROR(__xludf.DUMMYFUNCTION("LET( t, LOWER(TRIM(E5)), IFS( REGEXMATCH(t,""chuyển giới|transgender""), 6, REGEXMATCH(t,""vô tính|asexual|nam nữ.*không có nhu cầu""), 4, REGEXMATCH(t,""toàn tính|pansexual""), 5, REGEXMATCH(t,""song tính|bisexual|biromantic""), 1, "&" AND(REGEXMATCH(t,""đồng tính nam|\bgay\b""), NOT(REGEXMATCH(t,""not gay|không gay|ko gay""))), 2, REGEXMATCH(t,""đồng tính nữ|\blesbian\b|em thích nữ|thích nữ|mê nữ|sapphic""), 3, REGEXMATCH(t,""^\.$|^(không|ko|k|no)$|^(không có|ko có)$""), 8, "&" REGEXMATCH(t,""không biết|chưa rõ|chưa xác định|ko hiểu|huh|strange|\?{3,}|hong có.*không biết|vn chỉ có nam và nữ""), 7, REGEXMATCH(t,""dị tính|heterosexual|thẳng|straight|khác giới|thích khác giới|trai gái|quan hệ trai gái|nam\s*-\s*nữ|nam\s*nữ|b"&"ình thường|normal|\bbth\b|\bbinh thuong\b|giới tính bình thường|xu hướng tính dục bth""), 0, TRUE, 7 ) )"),0.0) -> 0 | G5: Phật giáo | H5: =IFERROR(__xludf.DUMMYFUNCTION("LET( t, LOWER(TRIM(G5)), IFS( REGEXMATCH(t,""phật giáo hòa hảo""), 3, REGEXMATCH(t,""công giáo""), 1, REGEXMATCH(t,""phật giáo""), 2, REGEXMATCH(t,""hồi giáo""), 4, REGEXMATCH(t,""cao đài|cao dai""), 5, REGEXMATCH(t,""bà la môn"&"|ba la mon""), 6, REGEXMATCH(t,""^kinh$""), 7, REGEXMATCH(t,""không tôn giáo|^(không|khong)$|^không có$|^khong co$|^không$|^không\s+$""), 0, TRUE, """" ) )"),2.0) -> 2 | I5: Thuê trọ | J5: =IFERROR(__xludf.DUMMYFUNCTION("LET( text, LOWER(I5), IFERROR( IFS( REGEXMATCH(text,""ở cùng gia đình|ở trọ cùng gia đình""), 0, REGEXMATCH(text,""thuê trọ""), 1, REGEXMATCH(text,""ở ktx""), 2, REGEXMATCH(text,""có nhà tại khu vực đang học|có nhà|ở riêng "&"tại chung cư""), 3, REGEXMATCH(text,""ở nhà người quen""), 4 ), -1) )"),1.0) -> 1 | K5: Trung bình | L5: =IFERROR(__xludf.DUMMYFUNCTION("LET( t, LOWER(TRIM(K5)), IFERROR( IFS( REGEXMATCH(t,""xuất\s*sắc""), 0, REGEXMATCH(t,""^giỏi$""), 1, REGEXMATCH(t,""^khá$""), 2, REGEXMATCH(t,""trung bình|bình thường|^4$""), 3, REGEXMATCH(t,""rớt""), 4, REGEXMA"&"TCH(t,""năm nhất|tân sinh viên|mới|chưa|không|sắp thi|chuẩn bị thi|kq|kết quả|chưa có|chưa biết""), 5, TRUE, 5 ), 5) )"),3.0) -> 3 | M5: Tự chọn | N5: =IFERROR(__xludf.DUMMYFUNCTION("LET( t, LOWER(TRIM(M5)), IFERROR( IFS( REGEXMATCH(t,""ko biết|không biết|hơm bt|hôm bt|khum biết|chưa biết|không rõ|câu không rõ""), 3, REGEXMATCH(t,""50/50|bình thường|phân vân|lúc này lúc kia|fomo|đuối|hơi đuối|hơi không chắc""), 1,"&" REGEXMATCH(t,""không hợp|không phù hợp|hối hận|bất đắc dĩ|bất đắt dĩ|do không còn lựa chọn|không còn đam mê|mất đam mê|học không nổi""), 0, REGEXMATCH(t,""^có$|^có\b""), 0, REGEXMATCH(t,""^không$|^không\s|^không\.$|^không!$|^không,$|^"&"không\?$|phù hợp|siêu hợp|cảm thấy phù hợp|phù hợp rồi|ổn|ước mơ|tự chọn|năng lực|suy nghĩ""), 2, TRUE, 3 ), 3) )"),2.0) -> 2 | O5: Có | P5: =if(O5="Có", 1, 0) -> 1 | Q5: 2 | R5: =Q5 -> 2 | S5: Nhân viên phục vụ, bán hàng | U5: <=40h/ tuần | V5: =IFERROR(__xludf.DUMMYFUNCTION("IFERROR(REGEXEXTRACT(U5,""\d+"")*1, """")"),40.0) -> 40 | W5: =if(V5<>"", V5, 0) -> 40 | X5: 0.7 | Y5: 0.5 | Z5: Không | AB5: Không | AC5: Không | AD5: Có một chút | AE5: Không | AF5: Không áp lực | AG5: Không ảnh hưởng | AH5: Không ảnh hưởng | AI5: Không bao giờ | AJ5: =LET( txt,LOWER(TRIM(SUBSTITUTE(AI5,CHAR(160)," "))), IFS( txt="không bao giờ",0, txt="hiếm khi (1–2 lần)",1, txt="thỉnh thoảng (vài lần)",2, txt="thường xuyên (thường xuyên trong vài tháng)",3, txt="luôn/rất thường xuyên",4, TRUE,"" ) ) -> 0 | AK5: Không ảnh hưởng | AL5: =LET( txt,LOWER(TRIM(SUBSTITUTE(AK5,CHAR(160)," "))), IFS( OR( ISNUMBER(SEARCH("không có trải nghiệm",txt)), ISNUMBER(SEARCH("chưa từng",txt)) ),-1, txt="không ảnh hưởng",0, ISNUMBER(SEARCH("có chút",txt)),1, AND(ISNUMBER(SEARCH("ảnh hưởng",txt)),ISNUMBER(SEARCH("rất",txt))),3, ISNUMBER(SEARCH("ảnh hưởng nhiều",txt)),2, TRUE,"" ) ) -> 0 | AM5: Độc thân | AN5: =LET( txt,LOWER(TRIM(AM5)), IFS( OR( txt="độc thân", txt="chưa có ny", txt="không có người yêu !!!!", txt="ế", txt="không có bồ", txt="không có", txt=".", txt="không có người yêu", txt="chưa yêu ai", txt="dạ chưa có mối tình đầu luôn ạ", txt="ko có người yêu", txt="đang kiếm phú bà nào đó ok ok", txt="án treo", txt="không", txt="ế quắt", txt="hiện tại không ai yêu và không quan tâm đến tình yêu", txt="0" ),0, txt="đã kết hôn",3, txt="trong mối quan hệ mập mờ",2, txt="có người yêu",1, TRUE,0 ) ) -> 0 | AP5: 1 | AQ5: 1 | AR5: 1 | AS5: 1 | AT5: 1 | AU5: 1 | AV5: 1 | AW5: 1 | AX5: 1 | AY5: =sum(AP5:AX5) -> 9 | AZ5: =AY5-9 -> 0 | BA5: =if(AZ5 >= 10 ,1,0) -> 0 | BB5: =if(AZ5 >= 14 ,1,0) -> 0 | BC5: 1 | BD5: 1 | BE5: 1 | BF5: 1 | BG5: 1 | BH5: 1 | BI5: 1 | BJ5: =sum(BC5:BI5) -> 7 | BK5: =BJ5-7 -> 0 | BN5: 1 | BO5: Không | BP5: =if(BO5="Không",0,1) -> 0 | BQ5: 1 | BR5: 0 | BS5: Không | BT5: =if(BS5="Không",0,1) -> 0 | BV5: 5 | BW5: Không | BX5: Cha mẹ | BY5: Có | BZ5: Không | CA5: =LET( txt,LOWER(TRIM(SUBSTITUTE(BZ5,CHAR(160)," "))), IFS( ISNUMBER(SEARCH("không",txt)),0, ISNUMBER(SEARCH("có một chút",txt)),1, ISNUMBER(SEARCH("thường xuyên",txt)),2, TRUE,"" ) ) -> 0 | CB5: Không | CC5: =LET( txt,LOWER(TRIM(SUBSTITUTE(CB5,CHAR(160)," "))), IFS( ISNUMBER(SEARCH("không",txt)),0, ISNUMBER(SEARCH("có một chút",txt)),1, ISNUMBER(SEARCH("thường xuyên",txt)),2, TRUE,"" ) ) -> 0 | CD5: Hiếm khi | CE5: =LET( txt,LOWER(TRIM(SUBSTITUTE(CD5,CHAR(160)," "))), IFS( ISNUMBER(SEARCH("hiếm khi",txt)),0, ISNUMBER(SEARCH("thỉnh thoảng",txt)),1, ISNUMBER(SEARCH("thường xuyên",txt)),2, TRUE,"" ) ) -> 0 | CF5: Hiếm khi | CG5: =LET( txt,LOWER(TRIM(SUBSTITUTE(CF5,CHAR(160)," "))), IFS( ISNUMBER(SEARCH("hiếm khi",txt)),0, ISNUMBER(SEARCH("thỉnh thoảng",txt)),1, ISNUMBER(SEARCH("thường xuyên",txt)),2, TRUE,"" ) ) -> 0 | CH5: Hiếm khi | CI5: =LET( txt,LOWER(TRIM(SUBSTITUTE(CH5,CHAR(160)," "))), IFS( ISNUMBER(SEARCH("hiếm khi",txt)),0, ISNUMBER(SEARCH("thỉnh thoảng",txt)),1, ISNUMBER(SEARCH("thường xuyên",txt)),2, TRUE,"" ) ) -> 0 | CJ5: Game | CK5: Phân biệt đối xử dựa trên bản dạng xã hội, Sức khỏe thể chất, tinh thần, tình dục hoặc các hình thức khác, Các vấn đề liên quan đến tâm linh, tôn giáo hoặc văn hóa, Các chủ đề về môi trường, Các chủ đề chính trị, Bạo lực tình dục, Các chủ đề liên quan đến bạo lực khác | CL5: 1-2 giờ mỗi ngày | CM5: =IFS( ISNUMBER(SEARCH("10-30",CL5)),0.33, ISNUMBER(SEARCH("31-60",CL5)),0.75, ISNUMBER(SEARCH("1-2",CL5)),1.5, ISNUMBER(SEARCH("3-4",CL5)),3.5, ISNUMBER(SEARCH("Hơn 5",CL5)),6, ISNUMBER(SEARCH("9 giờ",CL5)),9, ISNUMBER(SEARCH("18",CL5)),18, ISNUMBER(SEARCH("Không có",CL5)),0, ISNUMBER(SEARCH("Cả ngày",CL5)),18, ISNUMBER(SEARCH("Mọi lúc",CL5)),18, ISNUMBER(SEARCH("Hàng giờ",CL5)),12, ISNUMBER(SEARCH("không cố định",LOWER(CL5))),NA(), ISNUMBER(SEARCH("không theo",LOWER(CL5))),NA(), ISNUMBER(SEARCH("tranh thủ",LOWER(CL5))),NA(), ISNUMBER(SEARCH("tùy",LOWER(CL5))),NA(), ISNUMBER(SEARCH("sau 10h",LOWER(CL5))),2, TRUE,NA() ) -> 1.5 | CN5: Không | CO5: =if(CN5="Không", 0, if(CN5="Nhiều", 2, 1)) -> 0 | CP5: Không | CQ5: Không | CR5: Không | CS5: Không | CT5: Không | CU5: =if(CP5="Không",0,1) -> 0 | CV5: =if(CQ5="Không",0,1) -> 0 | CW5: =if(CR5="Không",0,1) -> 0 | CX5: =if(CS5="Không",0,1) -> 0 | CY5: =if(CT5="Không",0,1) -> 0 | CZ5: Không | DA5: =if(CZ5="Không",0,1) -> 0 | DB5: Không | DC5: =if(DB5="Không",0,1) -> 0 | DE5: Có | DF5: =if(DE5="Có", 1, 0) -> 1 | DG5: Không có | DH5: =if(DG5="Không có", 0, 1) -> 0 | DI5: Không | DJ5: =if(DI5="Không", 0, 1) -> 0 | DK5: Không, không bao giờ | DL5: =IFS( ISNUMBER(SEARCH("không",LOWER(DK5))),0, ISNUMBER(SEARCH("chưa",LOWER(DK5))),0, ISNUMBER(SEARCH("cả hai",LOWER(DK5))),3, AND(ISNUMBER(SEARCH("trước",LOWER(DK5))),ISNUMBER(SEARCH("đại học",LOWER(DK5)))),1, AND(ISNUMBER(SEARCH("kể từ khi",LOWER(DK5))),ISNUMBER(SEARCH("đại học",LOWER(DK5)))),2, ISNUMBER(SEARCH("thuốc",LOWER(DK5))),2, ISNUMBER(SEARCH("bác sĩ",LOWER(DK5))),2, TRUE,NA() ) -> 0 | DM5: 1-2 giờ | DN5: =LET( x,LOWER(TRIM(DM5)), IF(OR(x="không",x="0",x="hồi đó giờ ko chơi",x="hồi đó giờ không chơi"),0, IF(ISNUMBER(SEARCH("dưới 1",x)),0.5, IF(ISNUMBER(SEARCH("5 giờ trở lên",x)),5, IF(ISNUMBER(SEARCH("mỗi ngày",x)), IF(ISNUMBER(SEARCH("mỗi ngày ",x)), VALUE(MID(x,SEARCH("mỗi ngày ",x)+9,SEARCH(" giờ",x)-SEARCH("mỗi ngày ",x)-9))*7, VALUE(LEFT(x,SEARCH(" giờ",x)-1))*7 ), IF(ISNUMBER(SEARCH("-",x)), (VALUE(LEFT(x,SEARCH("-",x)-1))+VALUE(MID(x,SEARCH("-",x)+1,SEARCH(" giờ",x)-SEARCH("-",x)-1)))/2, IF(ISNUMBER(SEARCH(" giờ",x)), VALUE(LEFT(x,SEARCH(" giờ",x)-1)), "")))))) ) -> 1.5 | DO5: Chạy bộ, Đi bộ, Bơi lội | DP5: Không | DQ5: =IF(DP5 = "Không", 0, 1) -> 0 | DS5: Không | DU5: Không
A6: 46003.627 | B6: Lâm Đồng | C6: Nam | D6: =if(C6="Nam", 0, 1) -> 0 | E6: Trai thẳng 100% | F6: =IFERROR(__xludf.DUMMYFUNCTION("LET( t, LOWER(TRIM(E6)), IFS( REGEXMATCH(t,""chuyển giới|transgender""), 6, REGEXMATCH(t,""vô tính|asexual|nam nữ.*không có nhu cầu""), 4, REGEXMATCH(t,""toàn tính|pansexual""), 5, REGEXMATCH(t,""song tính|bisexual|biromantic""), 1, "&" AND(REGEXMATCH(t,""đồng tính nam|\bgay\b""), NOT(REGEXMATCH(t,""not gay|không gay|ko gay""))), 2, REGEXMATCH(t,""đồng tính nữ|\blesbian\b|em thích nữ|thích nữ|mê nữ|sapphic""), 3, REGEXMATCH(t,""^\.$|^(không|ko|k|no)$|^(không có|ko có)$""), 8, "&" REGEXMATCH(t,""không biết|chưa rõ|chưa xác định|ko hiểu|huh|strange|\?{3,}|hong có.*không biết|vn chỉ có nam và nữ""), 7, REGEXMATCH(t,""dị tính|heterosexual|thẳng|straight|khác giới|thích khác giới|trai gái|quan hệ trai gái|nam\s*-\s*nữ|nam\s*nữ|b"&"ình thường|normal|\bbth\b|\bbinh thuong\b|giới tính bình thường|xu hướng tính dục bth""), 0, TRUE, 7 ) )"),0.0) -> 0 | G6: Công giáo | H6: =IFERROR(__xludf.DUMMYFUNCTION("LET( t, LOWER(TRIM(G6)), IFS( REGEXMATCH(t,""phật giáo hòa hảo""), 3, REGEXMATCH(t,""công giáo""), 1, REGEXMATCH(t,""phật giáo""), 2, REGEXMATCH(t,""hồi giáo""), 4, REGEXMATCH(t,""cao đài|cao dai""), 5, REGEXMATCH(t,""bà la môn"&"|ba la mon""), 6, REGEXMATCH(t,""^kinh$""), 7, REGEXMATCH(t,""không tôn giáo|^(không|khong)$|^không có$|^khong co$|^không$|^không\s+$""), 0, TRUE, """" ) )"),1.0) -> 1 | I6: Thuê trọ | J6: =IFERROR(__xludf.DUMMYFUNCTION("LET( text, LOWER(I6), IFERROR( IFS( REGEXMATCH(text,""ở cùng gia đình|ở trọ cùng gia đình""), 0, REGEXMATCH(text,""thuê trọ""), 1, REGEXMATCH(text,""ở ktx""), 2, REGEXMATCH(text,""có nhà tại khu vực đang học|có nhà|ở riêng "&"tại chung cư""), 3, REGEXMATCH(text,""ở nhà người quen""), 4 ), -1) )"),1.0) -> 1 | K6: Trung bình | L6: =IFERROR(__xludf.DUMMYFUNCTION("LET( t, LOWER(TRIM(K6)), IFERROR( IFS( REGEXMATCH(t,""xuất\s*sắc""), 0, REGEXMATCH(t,""^giỏi$""), 1, REGEXMATCH(t,""^khá$""), 2, REGEXMATCH(t,""trung bình|bình thường|^4$""), 3, REGEXMATCH(t,""rớt""), 4, REGEXMA"&"TCH(t,""năm nhất|tân sinh viên|mới|chưa|không|sắp thi|chuẩn bị thi|kq|kết quả|chưa có|chưa biết""), 5, TRUE, 5 ), 5) )"),3.0) -> 3 | M6: Do xu hướng thị trường | N6: =IFERROR(__xludf.DUMMYFUNCTION("LET( t, LOWER(TRIM(M6)), IFERROR( IFS( REGEXMATCH(t,""ko biết|không biết|hơm bt|hôm bt|khum biết|chưa biết|không rõ|câu không rõ""), 3, REGEXMATCH(t,""50/50|bình thường|phân vân|lúc này lúc kia|fomo|đuối|hơi đuối|hơi không chắc""), 1,"&" REGEXMATCH(t,""không hợp|không phù hợp|hối hận|bất đắc dĩ|bất đắt dĩ|do không còn lựa chọn|không còn đam mê|mất đam mê|học không nổi""), 0, REGEXMATCH(t,""^có$|^có\b""), 0, REGEXMATCH(t,""^không$|^không\s|^không\.$|^không!$|^không,$|^"&"không\?$|phù hợp|siêu hợp|cảm thấy phù hợp|phù hợp rồi|ổn|ước mơ|tự chọn|năng lực|suy nghĩ""), 2, TRUE, 3 ), 3) )"),3.0) -> 3 | O6: Không | P6: =if(O6="Có", 1, 0) -> 0 | R6: =Q6 | V6: =IFERROR(__xludf.DUMMYFUNCTION("IFERROR(REGEXEXTRACT(U6,""\d+"")*1, """")"),"") | W6: =if(V6<>"", V6, 0) -> 0 | Z6: Có một chút | AB6: Không | AC6: Không | AD6: Rất lo lắng | AE6: Không | AF6: Áp lực nhiều | AG6: Có chút ảnh hưởng | AH6: Có chút ảnh hưởng | AI6: Không bao giờ | AJ6: =LET( txt,LOWER(TRIM(SUBSTITUTE(AI6,CHAR(160)," "))), IFS( txt="không bao giờ",0, txt="hiếm khi (1–2 lần)",1, txt="thỉnh thoảng (vài lần)",2, txt="thường xuyên (thường xuyên trong vài tháng)",3, txt="luôn/rất thường xuyên",4, TRUE,"" ) ) -> 0 | AK6: Không ảnh hưởng | AL6: =LET( txt,LOWER(TRIM(SUBSTITUTE(AK6,CHAR(160)," "))), IFS( OR( ISNUMBER(SEARCH("không có trải nghiệm",txt)), ISNUMBER(SEARCH("chưa từng",txt)) ),-1, txt="không ảnh hưởng",0, ISNUMBER(SEARCH("có chút",txt)),1, AND(ISNUMBER(SEARCH("ảnh hưởng",txt)),ISNUMBER(SEARCH("rất",txt))),3, ISNUMBER(SEARCH("ảnh hưởng nhiều",txt)),2, TRUE,"" ) ) -> 0 | AM6: Có người yêu | AN6: =LET( txt,LOWER(TRIM(AM6)), IFS( OR( txt="độc thân", txt="chưa có ny", txt="không có người yêu !!!!", txt="ế", txt="không có bồ", txt="không có", txt=".", txt="không có người yêu", txt="chưa yêu ai", txt="dạ chưa có mối tình đầu luôn ạ", txt="ko có người yêu", txt="đang kiếm phú bà nào đó ok ok", txt="án treo", txt="không", txt="ế quắt", txt="hiện tại không ai yêu và không quan tâm đến tình yêu", txt="0" ),0, txt="đã kết hôn",3, txt="trong mối quan hệ mập mờ",2, txt="có người yêu",1, TRUE,0 ) ) -> 1 | AP6: 3 | AQ6: 3 | AR6: 2 | AS6: 3 | AT6: 3 | AU6: 2 | AV6: 2 | AW6: 1 | AX6: 1 | AY6: =sum(AP6:AX6) -> 20 | AZ6: =AY6-9 -> 11 | BA6: =if(AZ6 >= 10 ,1,0) -> 1 | BB6: =if(AZ6 >= 14 ,1,0) -> 0 | BC6: 3 | BD6: 4 | BE6: 4 | BF6: 1 | BG6: 2 | BH6: 1 | BI6: 1 | BJ6: =sum(BC6:BI6) -> 16 | BK6: =BJ6-7 -> 9 | BN6: 1 | BO6: Có | BP6: =if(BO6="Không",0,1) -> 1 | BQ6: 1 | BR6: 36 | BS6: Có | BT6: =if(BS6="Không",0,1) -> 1 | BU6: Mạng xã hội | BV6: 3 | BW6: Có | BX6: Cha mẹ | BY6: Không | BZ6: Thường xuyên | CA6: =LET( txt,LOWER(TRIM(SUBSTITUTE(BZ6,CHAR(160)," "))), IFS( ISNUMBER(SEARCH("không",txt)),0, ISNUMBER(SEARCH("có một chút",txt)),1, ISNUMBER(SEARCH("thường xuyên",txt)),2, TRUE,"" ) ) -> 2 | CB6: Thường xuyên | CC6: =LET( txt,LOWER(TRIM(SUBSTITUTE(CB6,CHAR(160)," "))), IFS( ISNUMBER(SEARCH("không",txt)),0, ISNUMBER(SEARCH("có một chút",txt)),1, ISNUMBER(SEARCH("thường xuyên",txt)),2, TRUE,"" ) ) -> 2 | CD6: Thỉnh thoảng | CE6: =LET( txt,LOWER(TRIM(SUBSTITUTE(CD6,CHAR(160)," "))), IFS( ISNUMBER(SEARCH("hiếm khi",txt)),0, ISNUMBER(SEARCH("thỉnh thoảng",txt)),1, ISNUMBER(SEARCH("thường xuyên",txt)),2, TRUE,"" ) ) -> 1 | CF6: Thỉnh thoảng | CG6: =LET( txt,LOWER(TRIM(SUBSTITUTE(CF6,CHAR(160)," "))), IFS( ISNUMBER(SEARCH("hiếm khi",txt)),0, ISNUMBER(SEARCH("thỉnh thoảng",txt)),1, ISNUMBER(SEARCH("thường xuyên",txt)),2, TRUE,"" ) ) -> 1 | CH6: Thỉnh thoảng | CI6: =LET( txt,LOWER(TRIM(SUBSTITUTE(CH6,CHAR(160)," "))), IFS( ISNUMBER(SEARCH("hiếm khi",txt)),0, ISNUMBER(SEARCH("thỉnh thoảng",txt)),1, ISNUMBER(SEARCH("thường xuyên",txt)),2, TRUE,"" ) ) -> 1 | CJ6: Game | CK6: Các chủ đề chính trị | CL6: Hơn 5 giờ mỗi ngày | CM6: =IFS( ISNUMBER(SEARCH("10-30",CL6)),0.33, ISNUMBER(SEARCH("31-60",CL6)),0.75, ISNUMBER(SEARCH("1-2",CL6)),1.5, ISNUMBER(SEARCH("3-4",CL6)),3.5, ISNUMBER(SEARCH("Hơn 5",CL6)),6, ISNUMBER(SEARCH("9 giờ",CL6)),9, ISNUMBER(SEARCH("18",CL6)),18, ISNUMBER(SEARCH("Không có",CL6)),0, ISNUMBER(SEARCH("Cả ngày",CL6)),18, ISNUMBER(SEARCH("Mọi lúc",CL6)),18, ISNUMBER(SEARCH("Hàng giờ",CL6)),12, ISNUMBER(SEARCH("không cố định",LOWER(CL6))),NA(), ISNUMBER(SEARCH("không theo",LOWER(CL6))),NA(), ISNUMBER(SEARCH("tranh thủ",LOWER(CL6))),NA(), ISNUMBER(SEARCH("tùy",LOWER(CL6))),NA(), ISNUMBER(SEARCH("sau 10h",LOWER(CL6))),2, TRUE,NA() ) -> 6 | CN6: Không | CO6: =if(CN6="Không", 0, if(CN6="Nhiều", 2, 1)) -> 0 | CP6: Không | CQ6: Không | CR6: Không | CS6: Không | CT6: Không | CU6: =if(CP6="Không",0,1) -> 0 | CV6: =if(CQ6="Không",0,1) -> 0 | CW6: =if(CR6="Không",0,1) -> 0 | CX6: =if(CS6="Không",0,1) -> 0 | CY6: =if(CT6="Không",0,1) -> 0 | CZ6: Không | DA6: =if(CZ6="Không",0,1) -> 0 | DB6: Không | DC6: =if(DB6="Không",0,1) -> 0 | DE6: Không | DF6: =if(DE6="Có", 1, 0) -> 0 | DG6: Không có | DH6: =if(DG6="Không có", 0, 1) -> 0 | DI6: Không | DJ6: =if(DI6="Không", 0, 1) -> 0 | DK6: Không, không bao giờ | DL6: =IFS( ISNUMBER(SEARCH("không",LOWER(DK6))),0, ISNUMBER(SEARCH("chưa",LOWER(DK6))),0, ISNUMBER(SEARCH("cả hai",LOWER(DK6))),3, AND(ISNUMBER(SEARCH("trước",LOWER(DK6))),ISNUMBER(SEARCH("đại học",LOWER(DK6)))),1, AND(ISNUMBER(SEARCH("kể từ khi",LOWER(DK6))),ISNUMBER(SEARCH("đại học",LOWER(DK6)))),2, ISNUMBER(SEARCH("thuốc",LOWER(DK6))),2, ISNUMBER(SEARCH("bác sĩ",LOWER(DK6))),2, TRUE,NA() ) -> 0 | DN6: =LET( x,LOWER(TRIM(DM6)), IF(OR(x="không",x="0",x="hồi đó giờ ko chơi",x="hồi đó giờ không chơi"),0, IF(ISNUMBER(SEARCH("dưới 1",x)),0.5, IF(ISNUMBER(SEARCH("5 giờ trở lên",x)),5, IF(ISNUMBER(SEARCH("mỗi ngày",x)), IF(ISNUMBER(SEARCH("mỗi ngày ",x)), VALUE(MID(x,SEARCH("mỗi ngày ",x)+9,SEARCH(" giờ",x)-SEARCH("mỗi ngày ",x)-9))*7, VALUE(LEFT(x,SEARCH(" giờ",x)-1))*7 ), IF(ISNUMBER(SEARCH("-",x)), (VALUE(LEFT(x,SEARCH("-",x)-1))+VALUE(MID(x,SEARCH("-",x)+1,SEARCH(" giờ",x)-SEARCH("-",x)-1)))/2, IF(ISNUMBER(SEARCH(" giờ",x)), VALUE(LEFT(x,SEARCH(" giờ",x)-1)), "")))))) ) | DP6: Không | DQ6: =IF(DP6 = "Không", 0, 1) -> 0 | DS6: Không | DU6: Không
A7: 46003.627 | B7: Quảng Ngãi | C7: Nam | D7: =if(C7="Nam", 0, 1) -> 0 | E7: thẳng | F7: =IFERROR(__xludf.DUMMYFUNCTION("LET( t, LOWER(TRIM(E7)), IFS( REGEXMATCH(t,""chuyển giới|transgender""), 6, REGEXMATCH(t,""vô tính|asexual|nam nữ.*không có nhu cầu""), 4, REGEXMATCH(t,""toàn tính|pansexual""), 5, REGEXMATCH(t,""song tính|bisexual|biromantic""), 1, "&" AND(REGEXMATCH(t,""đồng tính nam|\bgay\b""), NOT(REGEXMATCH(t,""not gay|không gay|ko gay""))), 2, REGEXMATCH(t,""đồng tính nữ|\blesbian\b|em thích nữ|thích nữ|mê nữ|sapphic""), 3, REGEXMATCH(t,""^\.$|^(không|ko|k|no)$|^(không có|ko có)$""), 8, "&" REGEXMATCH(t,""không biết|chưa rõ|chưa xác định|ko hiểu|huh|strange|\?{3,}|hong có.*không biết|vn chỉ có nam và nữ""), 7, REGEXMATCH(t,""dị tính|heterosexual|thẳng|straight|khác giới|thích khác giới|trai gái|quan hệ trai gái|nam\s*-\s*nữ|nam\s*nữ|b"&"ình thường|normal|\bbth\b|\bbinh thuong\b|giới tính bình thường|xu hướng tính dục bth""), 0, TRUE, 7 ) )"),0.0) -> 0 | G7: Phật giáo | H7: =IFERROR(__xludf.DUMMYFUNCTION("LET( t, LOWER(TRIM(G7)), IFS( REGEXMATCH(t,""phật giáo hòa hảo""), 3, REGEXMATCH(t,""công giáo""), 1, REGEXMATCH(t,""phật giáo""), 2, REGEXMATCH(t,""hồi giáo""), 4, REGEXMATCH(t,""cao đài|cao dai""), 5, REGEXMATCH(t,""bà la môn"&"|ba la mon""), 6, REGEXMATCH(t,""^kinh$""), 7, REGEXMATCH(t,""không tôn giáo|^(không|khong)$|^không có$|^khong co$|^không$|^không\s+$""), 0, TRUE, """" ) )"),2.0) -> 2 | I7: Thuê trọ | J7: =IFERROR(__xludf.DUMMYFUNCTION("LET( text, LOWER(I7), IFERROR( IFS( REGEXMATCH(text,""ở cùng gia đình|ở trọ cùng gia đình""), 0, REGEXMATCH(text,""thuê trọ""), 1, REGEXMATCH(text,""ở ktx""), 2, REGEXMATCH(text,""có nhà tại khu vực đang học|có nhà|ở riêng "&"tại chung cư""), 3, REGEXMATCH(text,""ở nhà người quen""), 4 ), -1) )"),1.0) -> 1 | K7: Rớt môn | L7: =IFERROR(__xludf.DUMMYFUNCTION("LET( t, LOWER(TRIM(K7)), IFERROR( IFS( REGEXMATCH(t,""xuất\s*sắc""), 0, REGEXMATCH(t,""^giỏi$""), 1, REGEXMATCH(t,""^khá$""), 2, REGEXMATCH(t,""trung bình|bình thường|^4$""), 3, REGEXMATCH(t,""rớt""), 4, REGEXMA"&"TCH(t,""năm nhất|tân sinh viên|mới|chưa|không|sắp thi|chuẩn bị thi|kq|kết quả|chưa có|chưa biết""), 5, TRUE, 5 ), 5) )"),4.0) -> 4 | M7: Do xu hướng thị trường | N7: =IFERROR(__xludf.DUMMYFUNCTION("LET( t, LOWER(TRIM(M7)), IFERROR( IFS( REGEXMATCH(t,""ko biết|không biết|hơm bt|hôm bt|khum biết|chưa biết|không rõ|câu không rõ""), 3, REGEXMATCH(t,""50/50|bình thường|phân vân|lúc này lúc kia|fomo|đuối|hơi đuối|hơi không chắc""), 1,"&" REGEXMATCH(t,""không hợp|không phù hợp|hối hận|bất đắc dĩ|bất đắt dĩ|do không còn lựa chọn|không còn đam mê|mất đam mê|học không nổi""), 0, REGEXMATCH(t,""^có$|^có\b""), 0, REGEXMATCH(t,""^không$|^không\s|^không\.$|^không!$|^không,$|^"&"không\?$|phù hợp|siêu hợp|cảm thấy phù hợp|phù hợp rồi|ổn|ước mơ|tự chọn|năng lực|suy nghĩ""), 2, TRUE, 3 ), 3) )"),3.0) -> 3 | O7: Có | P7: =if(O7="Có", 1, 0) -> 1 | Q7: 1 | R7: =Q7 -> 1 | S7: Xe ôm | U7: <=40h/ tuần | V7: =IFERROR(__xludf.DUMMYFUNCTION("IFERROR(REGEXEXTRACT(U7,""\d+"")*1, """")"),40.0) -> 40 | W7: =if(V7<>"", V7, 0) -> 40 | X7: 1000 | Y7: 15000 | Z7: Không | AB7: Không | AC7: Không | AD7: Rất lo lắng | AE7: Có một chút | AF7: Rất áp lực | AG7: Ảnh hưởng rất nhiều | AH7: Không ảnh hưởng | AI7: Không bao giờ | AJ7: =LET( txt,LOWER(TRIM(SUBSTITUTE(AI7,CHAR(160)," "))), IFS( txt="không bao giờ",0, txt="hiếm khi (1–2 lần)",1, txt="thỉnh thoảng (vài lần)",2, txt="thường xuyên (thường xuyên trong vài tháng)",3, txt="luôn/rất thường xuyên",4, TRUE,"" ) ) -> 0 | AK7: Không ảnh hưởng | AL7: =LET( txt,LOWER(TRIM(SUBSTITUTE(AK7,CHAR(160)," "))), IFS( OR( ISNUMBER(SEARCH("không có trải nghiệm",txt)), ISNUMBER(SEARCH("chưa từng",txt)) ),-1, txt="không ảnh hưởng",0, ISNUMBER(SEARCH("có chút",txt)),1, AND(ISNUMBER(SEARCH("ảnh hưởng",txt)),ISNUMBER(SEARCH("rất",txt))),3, ISNUMBER(SEARCH("ảnh hưởng nhiều",txt)),2, TRUE,"" ) ) -> 0 | AM7: Có người yêu | AN7: =LET( txt,LOWER(TRIM(AM7)), IFS( OR( txt="độc thân", txt="chưa có ny", txt="không có người yêu !!!!", txt="ế", txt="không có bồ", txt="không có", txt=".", txt="không có người yêu", txt="chưa yêu ai", txt="dạ chưa có mối tình đầu luôn ạ", txt="ko có người yêu", txt="đang kiếm phú bà nào đó ok ok", txt="án treo", txt="không", txt="ế quắt", txt="hiện tại không ai yêu và không quan tâm đến tình yêu", txt="0" ),0, txt="đã kết hôn",3, txt="trong mối quan hệ mập mờ",2, txt="có người yêu",1, TRUE,0 ) ) -> 1 | AP7: 4 | AQ7: 4 | AR7: 4 | AS7: 4 | AT7: 4 | AU7: 4 | AV7: 4 | AW7: 4 | AX7: 4 | AY7: =sum(AP7:AX7) -> 36 | AZ7: =AY7-9 -> 27 | BA7: =if(AZ7 >= 10 ,1,0) -> 1 | BB7: =if(AZ7 >= 14 ,1,0) -> 1 | BC7: 4 | BD7: 4 | BE7: 4 | BF7: 4 | BG7: 4 | BH7: 4 | BI7: 4 | BJ7: =sum(BC7:BI7) -> 28 | BK7: =BJ7-7 -> 21 | BN7: 5 | BO7: Không | BP7: =if(BO7="Không",0,1) -> 0 | BQ7: 6 | BR7: 3 | BS7: Không | BT7: =if(BS7="Không",0,1) -> 0 | BV7: 5 | BW7: Không | BX7: Tự bản thân | BY7: Không | BZ7: Không | CA7: =LET( txt,LOWER(TRIM(SUBSTITUTE(BZ7,CHAR(160)," "))), IFS( ISNUMBER(SEARCH("không",txt)),0, ISNUMBER(SEARCH("có một chút",txt)),1, ISNUMBER(SEARCH("thường xuyên",txt)),2, TRUE,"" ) ) -> 0 | CB7: Thường xuyên | CC7: =LET( txt,LOWER(TRIM(SUBSTITUTE(CB7,CHAR(160)," "))), IFS( ISNUMBER(SEARCH("không",txt)),0, ISNUMBER(SEARCH("có một chút",txt)),1, ISNUMBER(SEARCH("thường xuyên",txt)),2, TRUE,"" ) ) -> 2 | CD7: Thường xuyên | CE7: =LET( txt,LOWER(TRIM(SUBSTITUTE(CD7,CHAR(160)," "))), IFS( ISNUMBER(SEARCH("hiếm khi",txt)),0, ISNUMBER(SEARCH("thỉnh thoảng",txt)),1, ISNUMBER(SEARCH("thường xuyên",txt)),2, TRUE,"" ) ) -> 2 | CF7: Thường xuyên | CG7: =LET( txt,LOWER(TRIM(SUBSTITUTE(CF7,CHAR(160)," "))), IFS( ISNUMBER(SEARCH("hiếm khi",txt)),0, ISNUMBER(SEARCH("thỉnh thoảng",txt)),1, ISNUMBER(SEARCH("thường xuyên",txt)),2, TRUE,"" ) ) -> 2 | CH7: Thường xuyên | CI7: =LET( txt,LOWER(TRIM(SUBSTITUTE(CH7,CHAR(160)," "))), IFS( ISNUMBER(SEARCH("hiếm khi",txt)),0, ISNUMBER(SEARCH("thỉnh thoảng",txt)),1, ISNUMBER(SEARCH("thường xuyên",txt)),2, TRUE,"" ) ) -> 2 | CJ7: Game | CK7: Các chủ đề về môi trường | CL7: Không có gì cả | CM7: =IFS( ISNUMBER(SEARCH("10-30",CL7)),0.33, ISNUMBER(SEARCH("31-60",CL7)),0.75, ISNUMBER(SEARCH("1-2",CL7)),1.5, ISNUMBER(SEARCH("3-4",CL7)),3.5, ISNUMBER(SEARCH("Hơn 5",CL7)),6, ISNUMBER(SEARCH("9 giờ",CL7)),9, ISNUMBER(SEARCH("18",CL7)),18, ISNUMBER(SEARCH("Không có",CL7)),0, ISNUMBER(SEARCH("Cả ngày",CL7)),18, ISNUMBER(SEARCH("Mọi lúc",CL7)),18, ISNUMBER(SEARCH("Hàng giờ",CL7)),12, ISNUMBER(SEARCH("không cố định",LOWER(CL7))),NA(), ISNUMBER(SEARCH("không theo",LOWER(CL7))),NA(), ISNUMBER(SEARCH("tranh thủ",LOWER(CL7))),NA(), ISNUMBER(SEARCH("tùy",LOWER(CL7))),NA(), ISNUMBER(SEARCH("sau 10h",LOWER(CL7))),2, TRUE,NA() ) -> 0 | CN7: Nhiều | CO7: =if(CN7="Không", 0, if(CN7="Nhiều", 2, 1)) -> 2 | CP7: Không | CQ7: Không | CR7: Không | CS7: Không | CT7: Không | CU7: =if(CP7="Không",0,1) -> 0 | CV7: =if(CQ7="Không",0,1) -> 0 | CW7: =if(CR7="Không",0,1) -> 0 | CX7: =if(CS7="Không",0,1) -> 0 | CY7: =if(CT7="Không",0,1) -> 0 | CZ7: Không | DA7: =if(CZ7="Không",0,1) -> 0 | DB7: Không | DC7: =if(DB7="Không",0,1) -> 0 | DE7: Không | DF7: =if(DE7="Có", 1, 0) -> 0 | DG7: Bệnh tuyến giáp (ví dụ: suy giáp,cường giáp) | DH7: =if(DG7="Không có", 0, 1) -> 1 | DI7: Rối loạn ám ảnh cưỡng chế hoặc liên quan (ví dụ: rối loạn ám ảnh cưỡng chế, rối loạn ngoại hình) | DJ7: =if(DI7="Không", 0, 1) -> 1 | DK7: Có, cả hai điều trên (trước khi vào đại học và kể từ khi vào đại học) | DL7: =IFS( ISNUMBER(SEARCH("không",LOWER(DK7))),0, ISNUMBER(SEARCH("chưa",LOWER(DK7))),0, ISNUMBER(SEARCH("cả hai",LOWER(DK7))),3, AND(ISNUMBER(SEARCH("trước",LOWER(DK7))),ISNUMBER(SEARCH("đại học",LOWER(DK7)))),1, AND(ISNUMBER(SEARCH("kể từ khi",LOWER(DK7))),ISNUMBER(SEARCH("đại học",LOWER(DK7)))),2, ISNUMBER(SEARCH("thuốc",LOWER(DK7))),2, ISNUMBER(SEARCH("bác sĩ",LOWER(DK7))),2, TRUE,NA() ) -> 3 | DN7: =LET( x,LOWER(TRIM(DM7)), IF(OR(x="không",x="0",x="hồi đó giờ ko chơi",x="hồi đó giờ không chơi"),0, IF(ISNUMBER(SEARCH("dưới 1",x)),0.5, IF(ISNUMBER(SEARCH("5 giờ trở lên",x)),5, IF(ISNUMBER(SEARCH("mỗi ngày",x)), IF(ISNUMBER(SEARCH("mỗi ngày ",x)), VALUE(MID(x,SEARCH("mỗi ngày ",x)+9,SEARCH(" giờ",x)-SEARCH("mỗi ngày ",x)-9))*7, VALUE(LEFT(x,SEARCH(" giờ",x)-1))*7 ), IF(ISNUMBER(SEARCH("-",x)), (VALUE(LEFT(x,SEARCH("-",x)-1))+VALUE(MID(x,SEARCH("-",x)+1,SEARCH(" giờ",x)-SEARCH("-",x)-1)))/2, IF(ISNUMBER(SEARCH(" giờ",x)), VALUE(LEFT(x,SEARCH(" giờ",x)-1)), "")))))) ) | DP7: Không | DQ7: =IF(DP7 = "Không", 0, 1) -> 0 | DS7: Không | DU7: Có, cố ý" | DW7: Không giữ em bé
